{
    "source": "BDSA",
    "name": "BDSA-2021-3824",
    "title": "NumPy Vulnerable to Denial-of-Service (DoS) via Buffer Overflow in 'PyArray_NewFromDescr_int' Function",
    "description": "NumPy is vulnerable to denial-of-service (DoS) due to improper handling of multi-array operations. An attacker could exploit this vulnerability by supplying an application with maliciously crafted large-dimensional arrays.",
    "technicalDescription": "The issue exists in the function `PyArray_NewFromDescr_int()` within the file `numpy/core/src/multiarray/ctors.c`. Insufficient bounds checking of array dimensions can result in a buffer overflow and a DoS condition when processing large-dimensional arrays.",
    "publishedDate": "2021-12-20T15:48:22.422Z",
    "updatedDate": "2021-12-20T15:48:22.408Z",
    "disclosureDate": "2021-05-07T00:00:00.000Z",
    "solution": "Fixed in **[1.21.0-rc1](https://github.com/numpy/numpy/releases/tag/v1.21.0rc1)** by [this](https://github.com/numpy/numpy/commit/ae317fd9f) commit.",
    "severity": "MEDIUM",
    "cvss2": {
        "baseScore": 5.0,
        "impactSubscore": 2.9,
        "exploitabilitySubscore": 10.0,
        "severity": "LOW",
        "accessVector": "NETWORK",
        "accessComplexity": "LOW",
        "authentication": "NONE",
        "confidentialityImpact": "NONE",
        "integrityImpact": "NONE",
        "availabilityImpact": "PARTIAL",
        "temporalMetrics": {
            "exploitability": "UNPROVEN",
            "remediationLevel": "OFFICIAL_FIX",
            "reportConfidence": "CONFIRMED",
            "score": 3.7
        },
        "vector": "(AV:N/AC:L/Au:N/C:N/I:N/A:P/E:U/RL:OF/RC:C)"
    },
    "cvss3": {
        "baseScore": 5.3,
        "impactSubscore": 1.4,
        "exploitabilitySubscore": 3.9,
        "severity": "MEDIUM",
        "attackVector": "NETWORK",
        "attackComplexity": "LOW",
        "confidentialityImpact": "NONE",
        "integrityImpact": "NONE",
        "availabilityImpact": "LOW",
        "privilegesRequired": "NONE",
        "scope": "UNCHANGED",
        "userInteraction": "NONE",
        "temporalMetrics": {
            "exploitability": "UNPROVEN",
            "remediationLevel": "OFFICIAL_FIX",
            "reportConfidence": "CONFIRMED",
            "score": 4.6
        },
        "vector": "CVSS:3.1/AV:N/AC:L/PR:N/UI:N/S:U/C:N/I:N/A:L/E:U/RL:O/RC:C"
    },
    "useCvss3": true,
    "classifications": [],
    "zeroDay": false,
    "underReview": false,
    "parentAdvisory": false,
    "workaround": "",
    "vendorFixDate": "2021-05-11T00:00:00.000Z",
    "bdsaTags": [],
    "overallScore": 4.6,
    "_meta": {
        "allow": [
            "GET"
        ],
        "href": "https://trendmicro2.app.blackduck.com/api/vulnerabilities/BDSA-2021-3824",
        "links": [
            {
                "rel": "cwes",
                "href": "https://trendmicro2.app.blackduck.com/api/cwes/CWE-120"
            },
            {
                "rel": "related-vulnerability",
                "href": "https://trendmicro2.app.blackduck.com/api/vulnerabilities/CVE-2021-33430",
                "label": "NVD"
            },
            {
                "rel": "bdsa-ranges",
                "href": "https://trendmicro2.app.blackduck.com/api/vulnerabilities/BDSA-2021-3824/ranges"
            },
            {
                "rel": "reference",
                "href": "https://github.com/numpy/numpy/commit/ae317fd9f",
                "label": "PATCH"
            },
            {
                "rel": "reference",
                "href": "https://github.com/numpy/numpy/issues/18939",
                "label": "ADVISORY"
            },
            {
                "rel": "reference",
                "href": "https://github.com/numpy/numpy/releases/tag/v1.21.0rc1",
                "label": "VENDOR_UPGRADE"
            },
            {
                "rel": "default-remediation-status",
                "href": "https://trendmicro2.app.blackduck.com/api/vulnerabilities/BDSA-2021-3824/default-remediation-status"
            }
        ]
    }
}