{
    "source": "BDSA",
    "name": "BDSA-2017-3363",
    "title": "Python Vulnerable to Denial-of-Service via Race Condition in \"readahead\"",
    "description": "A local attacker who can execute python code can cause a crash, resulting in a denial-of-service of the python interpreter.",
    "technicalDescription": "The `readahead` feature of `Objects/fileobject.c` is not thread safe. When reading from an object file concurrently a heap-buffer-overflow and use-after-free can occur.  An attacker an leverage this to cause a denial-of-service of the interpreter.",
    "publishedDate": "2018-06-01T09:38:24.722Z",
    "updatedDate": "2018-06-01T09:38:24.714Z",
    "disclosureDate": "2017-09-20T00:00:00.000Z",
    "exploitPublishDate": "2017-09-20T00:00:00.000Z",
    "solution": "Fixed in version [**2.7.15rc1**](https://github.com/python/cpython/releases/tag/v2.7.15rc1) by [this](https://github.com/python/cpython/commit/dbf52e02f18dac6f5f0a64f78932f3dc6efc056b) git commit.",
    "severity": "LOW",
    "cvss2": {
        "baseScore": 2.1,
        "impactSubscore": 2.9,
        "exploitabilitySubscore": 3.9,
        "severity": "LOW",
        "accessVector": "LOCAL",
        "accessComplexity": "LOW",
        "authentication": "NONE",
        "confidentialityImpact": "NONE",
        "integrityImpact": "NONE",
        "availabilityImpact": "PARTIAL",
        "temporalMetrics": {
            "exploitability": "PROOF_OF_CONCEPT",
            "remediationLevel": "OFFICIAL_FIX",
            "reportConfidence": "CONFIRMED",
            "score": 1.7
        },
        "vector": "(AV:L/AC:L/Au:N/C:N/I:N/A:P/E:POC/RL:OF/RC:C)"
    },
    "cvss3": {
        "baseScore": 4.0,
        "impactSubscore": 1.4,
        "exploitabilitySubscore": 2.5,
        "severity": "LOW",
        "attackVector": "LOCAL",
        "attackComplexity": "LOW",
        "confidentialityImpact": "NONE",
        "integrityImpact": "NONE",
        "availabilityImpact": "LOW",
        "privilegesRequired": "NONE",
        "scope": "UNCHANGED",
        "userInteraction": "NONE",
        "temporalMetrics": {
            "exploitability": "PROOF_OF_CONCEPT",
            "remediationLevel": "OFFICIAL_FIX",
            "reportConfidence": "CONFIRMED",
            "score": 3.6
        },
        "vector": "CVSS:3.0/AV:L/AC:L/PR:N/UI:N/S:U/C:N/I:N/A:L/E:P/RL:O/RC:C"
    },
    "useCvss3": true,
    "classifications": [],
    "zeroDay": false,
    "underReview": false,
    "parentAdvisory": false,
    "workaround": "",
    "vendorFixDate": "2018-04-14T00:00:00.000Z",
    "bdsaTags": [],
    "overallScore": 3.6,
    "_meta": {
        "allow": [],
        "href": "https://trendmicro.app.blackduck.com/api/vulnerabilities/BDSA-2017-3363",
        "links": [
            {
                "rel": "cwes",
                "href": "https://trendmicro.app.blackduck.com/api/cwes/CWE-366"
            },
            {
                "rel": "related-vulnerability",
                "href": "https://trendmicro.app.blackduck.com/api/vulnerabilities/CVE-2018-1000030",
                "label": "NVD"
            },
            {
                "rel": "bdsa-ranges",
                "href": "https://trendmicro.app.blackduck.com/api/vulnerabilities/BDSA-2017-3363/ranges"
            },
            {
                "rel": "reference",
                "href": "https://bugs.python.org/issue31530",
                "label": "POC"
            },
            {
                "rel": "reference",
                "href": "https://bugzilla.suse.com/1079300",
                "label": "ADVISORY"
            },
            {
                "rel": "reference",
                "href": "https://github.com/python/cpython/commit/dbf52e02f18dac6f5f0a64f78932f3dc6efc056b",
                "label": "PATCH"
            }
        ]
    }
}